2017-09-14 21:35:10,421 - INFO - start convert GDB...
                       source File Path:C:\Users\esri\Desktop\customerupdate
                       output Path:D:\dataHandle\GISData\gdb\crm\clientdata
                       log Path:E:\python_project\CMB-Py\dataManage\workspace\logs
2017-09-14 21:35:10,421 - INFO - insertUpdate ** update GDB soucefile:C:\Users\esri\Desktop\customerupdate
2017-09-14 21:35:10,701 - WARNING - [('D:\\dataHandle\\GISData\\arcgisserver\\gdb\\crm\\clientdata\\clientdata.gdb\\_gdb.T450.3236.8460.sr.lock', 'D:\\dataHandle\\GISData\\gdb\\crm\\clientdata\\clientdata.gdb\\_gdb.T450.3236.8460.sr.lock', "[Errno 13] Permission denied: 'D:\\\\dataHandle\\\\GISData\\\\arcgisserver\\\\gdb\\\\crm\\\\clientdata\\\\clientdata.gdb\\\\_gdb.T450.3236.8460.sr.lock'")]
2017-09-14 21:35:10,701 - WARNING - Traceback (most recent call last):
  File "E:/python_project/CMB-Py/dataManage/serverHandler/InsertGDB_update_multi.py", line 89, in ConvertGDB
    shutil.copytree(gdbServerPath, gdbPath)
  File "C:\Python27\ArcGIS10.2\lib\shutil.py", line 206, in copytree
    raise Error, errors
Error: [('D:\\dataHandle\\GISData\\arcgisserver\\gdb\\crm\\clientdata\\clientdata.gdb\\_gdb.T450.3236.8460.sr.lock', 'D:\\dataHandle\\GISData\\gdb\\crm\\clientdata\\clientdata.gdb\\_gdb.T450.3236.8460.sr.lock', "[Errno 13] Permission denied: 'D:\\\\dataHandle\\\\GISData\\\\arcgisserver\\\\gdb\\\\crm\\\\clientdata\\\\clientdata.gdb\\\\_gdb.T450.3236.8460.sr.lock'")]

2017-09-14 21:35:10,701 - INFO - insertUpdate ** convert error!
2017-09-14 21:35:50,930 - INFO - start convert GDB...
                       source File Path:C:\Users\esri\Desktop\customerupdate
                       output Path:D:\dataHandle\GISData\gdb\crm\clientdata
                       log Path:E:/python_project/CMB-Py/dataManage\workspace\logs
2017-09-14 21:35:53,642 - INFO - insertUpdate ** update GDB soucefile:C:\Users\esri\Desktop\customerupdate
2017-09-14 21:36:14,279 - INFO - build tempGDB...
2017-09-14 21:37:51,752 - INFO - start convert GDB...
                       source File Path:C:\Users\esri\Desktop\customerupdate
                       output Path:D:\dataHandle\GISData\gdb\crm\clientdata
                       log Path:E:\python_project\CMB-Py\dataManage\workspace\logs
2017-09-14 21:37:51,752 - INFO - insertUpdate ** update GDB soucefile:C:\Users\esri\Desktop\customerupdate
2017-09-14 21:37:51,891 - INFO - build tempGDB...
2017-09-14 21:38:08,951 - INFO - insert tempGDB to gdb...
2017-09-14 21:38:09,888 - WARNING - cannot open 'D:\dataHandle\GISData\gdb\crm\clientdata\tempdata.gdb'
2017-09-14 21:38:09,888 - WARNING - Traceback (most recent call last):
  File "E:/python_project/CMB-Py/dataManage/serverHandler/InsertGDB_update_multi.py", line 134, in ConvertGDB
    searchCursor = ac.searchData(os.path.join(gdbPath_temp), ["CID"])
  File "E:\python_project\CMB-Py\dataManage\serverHandler\arcpyControl\arcpyOp.py", line 228, in searchData
    return arcpy.da.SearchCursor(layerPath, field_names, where_clause)
RuntimeError: cannot open 'D:\dataHandle\GISData\gdb\crm\clientdata\tempdata.gdb'

2017-09-14 21:38:09,888 - INFO - insertUpdate ** convert error!
2017-09-14 21:41:29,114 - INFO - start convert GDB...
                       source File Path:C:\Users\esri\Desktop\customerupdate
                       output Path:D:\dataHandle\GISData\gdb\crm\clientdata
                       log Path:E:\python_project\CMB-Py\dataManage\workspace\logs
2017-09-14 21:41:29,114 - INFO - insertUpdate ** update GDB soucefile:C:\Users\esri\Desktop\customerupdate
2017-09-14 21:41:29,269 - INFO - build tempGDB...
2017-09-14 21:41:45,707 - INFO - insert tempGDB to gdb...
2017-09-14 21:41:50,989 - WARNING - Failed to execute. Parameters are not valid.
ERROR 000732: Target Dataset: Dataset D:\dataHandle\GISData\gdb\crm\clientdata\clientdata.gdb\clientdata100_ does not exist or is not supported
Failed to execute (Append).

2017-09-14 21:41:50,989 - WARNING - Traceback (most recent call last):
  File "E:/python_project/CMB-Py/dataManage/serverHandler/InsertGDB_update_multi.py", line 132, in ConvertGDB
    ac.appendLayers(os.path.join(gdbPath_temp, sn), os.path.join(gdbPath, sn))  # 与正式图层合并，完成新增插入
  File "E:\python_project\CMB-Py\dataManage\serverHandler\arcpyControl\arcpyOp.py", line 233, in appendLayers
    arcpy.Append_management(layers, output, 'TEST')
  File "C:\Program Files (x86)\ArcGIS\Desktop10.2\arcpy\arcpy\management.py", line 3614, in Append
    raise e
ExecuteError: Failed to execute. Parameters are not valid.
ERROR 000732: Target Dataset: Dataset D:\dataHandle\GISData\gdb\crm\clientdata\clientdata.gdb\clientdata100_ does not exist or is not supported
Failed to execute (Append).


2017-09-14 21:41:50,989 - INFO - insertUpdate ** convert error!
2017-09-14 21:44:21,486 - INFO - start convert GDB...
                       source File Path:C:\Users\esri\Desktop\customerupdate
                       output Path:D:\dataHandle\GISData\gdb\crm\clientdata
                       log Path:E:\python_project\CMB-Py\dataManage\workspace\logs
2017-09-14 21:44:21,486 - INFO - insertUpdate ** update GDB soucefile:C:\Users\esri\Desktop\customerupdate
2017-09-14 21:44:21,674 - INFO - build tempGDB...
2017-09-14 21:44:38,592 - INFO - insert tempGDB to gdb...
2017-09-14 21:44:44,249 - INFO - insertUpdate ** update GDB soucefile:C:\Users\esri\Desktop\customerupdate  complate！
2017-09-14 21:44:44,249 - INFO - insertUpdate ** convert success!
2017-09-14 21:46:06,430 - INFO - start convert GDB...
                       source File Path:C:\Users\esri\Desktop\customerupdate
                       output Path:D:\dataHandle\GISData\gdb\crm\clientdata
                       log Path:E:\python_project\CMB-Py\dataManage\workspace\logs
2017-09-14 21:46:06,430 - INFO - insertUpdate ** update GDB soucefile:C:\Users\esri\Desktop\customerupdate
2017-09-14 21:46:06,571 - INFO - build tempGDB...
2017-09-14 21:46:23,134 - INFO - update layer...
2017-09-14 21:46:23,414 - WARNING - unsupported operand type(s) for +: 'NoneType' and 'str'
2017-09-14 21:46:23,414 - WARNING - Traceback (most recent call last):
  File "E:/python_project/CMB-Py/dataManage/serverHandler/InsertGDB_update_multi.py", line 114, in ConvertGDB
    sqlStrs = buildSQLStr(sourceFilePath, tableViewPath, uniqueId)
  File "E:/python_project/CMB-Py/dataManage/serverHandler/InsertGDB_update_multi.py", line 40, in buildSQLStr
    sql = ac.addFieldDelimiters(layerPath, "CID") + " in (%s)"
TypeError: unsupported operand type(s) for +: 'NoneType' and 'str'

2017-09-14 21:46:23,414 - INFO - insertUpdate ** convert error!
2017-09-14 21:47:37,595 - INFO - start convert GDB...
                       source File Path:C:\Users\esri\Desktop\customerupdate
                       output Path:D:\dataHandle\GISData\gdb\crm\clientdata
                       log Path:E:/python_project/CMB-Py/dataManage\workspace\logs
2017-09-14 21:47:37,595 - INFO - insertUpdate ** update GDB soucefile:C:\Users\esri\Desktop\customerupdate
2017-09-14 21:47:38,016 - INFO - build tempGDB...
2017-09-14 21:48:21,884 - INFO - update layer...
2017-09-14 21:49:58,446 - INFO - start convert GDB...
                       source File Path:C:\Users\esri\Desktop\customerupdate
                       output Path:D:\dataHandle\GISData\gdb\crm\clientdata
                       log Path:E:\python_project\CMB-Py\dataManage\workspace\logs
2017-09-14 21:49:58,446 - INFO - insertUpdate ** update GDB soucefile:C:\Users\esri\Desktop\customerupdate
2017-09-14 21:49:58,618 - INFO - build tempGDB...
2017-09-14 21:50:15,039 - INFO - update layer...
2017-09-14 21:50:15,322 - WARNING - unsupported operand type(s) for +: 'NoneType' and 'str'
2017-09-14 21:50:15,322 - WARNING - Traceback (most recent call last):
  File "E:/python_project/CMB-Py/dataManage/serverHandler/InsertGDB_update_multi.py", line 114, in ConvertGDB
    sqlStrs = buildSQLStr(sourceFilePath, tableViewPath, uniqueId)
  File "E:/python_project/CMB-Py/dataManage/serverHandler/InsertGDB_update_multi.py", line 58, in buildSQLStr
    sqlStrs.append(sql + " in (%s)" % sqlStr)
TypeError: unsupported operand type(s) for +: 'NoneType' and 'str'

2017-09-14 21:50:15,322 - INFO - insertUpdate ** convert error!
2017-09-14 21:51:22,426 - INFO - start convert GDB...
                       source File Path:C:\Users\esri\Desktop\customerupdate
                       output Path:D:\dataHandle\GISData\gdb\crm\clientdata
                       log Path:E:/python_project/CMB-Py/dataManage\workspace\logs
2017-09-14 21:51:22,426 - INFO - insertUpdate ** update GDB soucefile:C:\Users\esri\Desktop\customerupdate
2017-09-14 21:51:22,612 - INFO - build tempGDB...
2017-09-14 21:51:52,878 - INFO - update layer...
2017-09-14 21:55:23,134 - INFO - start convert GDB...
                       source File Path:C:\Users\esri\Desktop\customerupdate
                       output Path:D:\dataHandle\GISData\gdb\crm\clientdata
                       log Path:E:\python_project\CMB-Py\dataManage\workspace\logs
2017-09-14 21:55:23,134 - INFO - insertUpdate ** update GDB soucefile:C:\Users\esri\Desktop\customerupdate
2017-09-14 21:55:23,167 - WARNING - 
2017-09-14 21:55:23,167 - WARNING - Traceback (most recent call last):
  File "E:/python_project/CMB-Py/dataManage/serverHandler/InsertGDB_update_multi.py", line 87, in ConvertGDB
    shutil.rmtree(gdbPath)
  File "C:\Python27\ArcGIS10.2\lib\shutil.py", line 250, in rmtree
    onerror(os.remove, fullname, sys.exc_info())
  File "C:\Python27\ArcGIS10.2\lib\shutil.py", line 248, in rmtree
    os.remove(fullname)
WindowsError: [Error 32] : 'D:\\dataHandle\\GISData\\gdb\\crm\\clientdata\\clientdata.gdb\\a00000010.gdbtable'

2017-09-14 21:55:23,167 - INFO - insertUpdate ** convert error!
2017-09-14 21:55:39,346 - INFO - start convert GDB...
                       source File Path:C:\Users\esri\Desktop\customerupdate
                       output Path:D:\dataHandle\GISData\gdb\crm\clientdata
                       log Path:E:\python_project\CMB-Py\dataManage\workspace\logs
2017-09-14 21:55:39,346 - INFO - insertUpdate ** update GDB soucefile:C:\Users\esri\Desktop\customerupdate
2017-09-14 21:55:39,535 - WARNING - [('D:\\dataHandle\\GISData\\arcgisserver\\gdb\\crm\\clientdata\\clientdata.gdb\\_gdb.T450.3236.8460.sr.lock', 'D:\\dataHandle\\GISData\\gdb\\crm\\clientdata\\clientdata.gdb\\_gdb.T450.3236.8460.sr.lock', "[Errno 13] Permission denied: 'D:\\\\dataHandle\\\\GISData\\\\arcgisserver\\\\gdb\\\\crm\\\\clientdata\\\\clientdata.gdb\\\\_gdb.T450.3236.8460.sr.lock'")]
2017-09-14 21:55:39,535 - WARNING - Traceback (most recent call last):
  File "E:/python_project/CMB-Py/dataManage/serverHandler/InsertGDB_update_multi.py", line 91, in ConvertGDB
    shutil.copytree(gdbServerPath, gdbPath)
  File "C:\Python27\ArcGIS10.2\lib\shutil.py", line 206, in copytree
    raise Error, errors
Error: [('D:\\dataHandle\\GISData\\arcgisserver\\gdb\\crm\\clientdata\\clientdata.gdb\\_gdb.T450.3236.8460.sr.lock', 'D:\\dataHandle\\GISData\\gdb\\crm\\clientdata\\clientdata.gdb\\_gdb.T450.3236.8460.sr.lock', "[Errno 13] Permission denied: 'D:\\\\dataHandle\\\\GISData\\\\arcgisserver\\\\gdb\\\\crm\\\\clientdata\\\\clientdata.gdb\\\\_gdb.T450.3236.8460.sr.lock'")]

2017-09-14 21:55:39,535 - INFO - insertUpdate ** convert error!
2017-09-14 21:56:12,177 - INFO - start convert GDB...
                       source File Path:C:\Users\esri\Desktop\customerupdate
                       output Path:D:\dataHandle\GISData\gdb\crm\clientdata
                       log Path:E:\python_project\CMB-Py\dataManage\workspace\logs
2017-09-14 21:56:12,177 - INFO - insertUpdate ** update GDB soucefile:C:\Users\esri\Desktop\customerupdate
2017-09-14 21:56:12,318 - WARNING - [('D:\\dataHandle\\GISData\\arcgisserver\\gdb\\crm\\clientdata\\clientdata.gdb\\_gdb.T450.3236.8460.sr.lock', 'D:\\dataHandle\\GISData\\gdb\\crm\\clientdata\\clientdata.gdb\\_gdb.T450.3236.8460.sr.lock', "[Errno 13] Permission denied: 'D:\\\\dataHandle\\\\GISData\\\\arcgisserver\\\\gdb\\\\crm\\\\clientdata\\\\clientdata.gdb\\\\_gdb.T450.3236.8460.sr.lock'")]
2017-09-14 21:56:12,318 - WARNING - Traceback (most recent call last):
  File "E:/python_project/CMB-Py/dataManage/serverHandler/InsertGDB_update_multi.py", line 91, in ConvertGDB
    shutil.copytree(gdbServerPath, gdbPath)
  File "C:\Python27\ArcGIS10.2\lib\shutil.py", line 206, in copytree
    raise Error, errors
Error: [('D:\\dataHandle\\GISData\\arcgisserver\\gdb\\crm\\clientdata\\clientdata.gdb\\_gdb.T450.3236.8460.sr.lock', 'D:\\dataHandle\\GISData\\gdb\\crm\\clientdata\\clientdata.gdb\\_gdb.T450.3236.8460.sr.lock', "[Errno 13] Permission denied: 'D:\\\\dataHandle\\\\GISData\\\\arcgisserver\\\\gdb\\\\crm\\\\clientdata\\\\clientdata.gdb\\\\_gdb.T450.3236.8460.sr.lock'")]

2017-09-14 21:56:12,334 - INFO - insertUpdate ** convert error!
2017-09-14 21:56:40,186 - INFO - start convert GDB...
                       source File Path:C:\Users\esri\Desktop\customerupdate
                       output Path:D:\dataHandle\GISData\gdb\crm\clientdata
                       log Path:E:\python_project\CMB-Py\dataManage\workspace\logs
2017-09-14 21:56:40,186 - INFO - insertUpdate ** update GDB soucefile:C:\Users\esri\Desktop\customerupdate
2017-09-14 21:56:40,374 - WARNING - [('D:\\dataHandle\\GISData\\arcgisserver\\gdb\\crm\\clientdata\\clientdata.gdb\\_gdb.T450.3236.8460.sr.lock', 'D:\\dataHandle\\GISData\\gdb\\crm\\clientdata\\clientdata.gdb\\_gdb.T450.3236.8460.sr.lock', "[Errno 13] Permission denied: 'D:\\\\dataHandle\\\\GISData\\\\arcgisserver\\\\gdb\\\\crm\\\\clientdata\\\\clientdata.gdb\\\\_gdb.T450.3236.8460.sr.lock'")]
2017-09-14 21:56:40,374 - WARNING - Traceback (most recent call last):
  File "E:/python_project/CMB-Py/dataManage/serverHandler/InsertGDB_update_multi.py", line 91, in ConvertGDB
    shutil.copytree(gdbServerPath, gdbPath)
  File "C:\Python27\ArcGIS10.2\lib\shutil.py", line 206, in copytree
    raise Error, errors
Error: [('D:\\dataHandle\\GISData\\arcgisserver\\gdb\\crm\\clientdata\\clientdata.gdb\\_gdb.T450.3236.8460.sr.lock', 'D:\\dataHandle\\GISData\\gdb\\crm\\clientdata\\clientdata.gdb\\_gdb.T450.3236.8460.sr.lock', "[Errno 13] Permission denied: 'D:\\\\dataHandle\\\\GISData\\\\arcgisserver\\\\gdb\\\\crm\\\\clientdata\\\\clientdata.gdb\\\\_gdb.T450.3236.8460.sr.lock'")]

2017-09-14 21:56:40,374 - INFO - insertUpdate ** convert error!
2017-09-14 21:56:54,361 - INFO - start convert GDB...
                       source File Path:C:\Users\esri\Desktop\customerupdate
                       output Path:D:\dataHandle\GISData\gdb\crm\clientdata
                       log Path:E:\python_project\CMB-Py\dataManage\workspace\logs
2017-09-14 21:56:54,361 - INFO - insertUpdate ** update GDB soucefile:C:\Users\esri\Desktop\customerupdate
2017-09-14 21:56:54,486 - WARNING - [('D:\\dataHandle\\GISData\\arcgisserver\\gdb\\crm\\clientdata\\clientdata.gdb\\_gdb.T450.3236.8460.sr.lock', 'D:\\dataHandle\\GISData\\gdb\\crm\\clientdata\\clientdata.gdb\\_gdb.T450.3236.8460.sr.lock', "[Errno 13] Permission denied: 'D:\\\\dataHandle\\\\GISData\\\\arcgisserver\\\\gdb\\\\crm\\\\clientdata\\\\clientdata.gdb\\\\_gdb.T450.3236.8460.sr.lock'")]
2017-09-14 21:56:54,486 - WARNING - Traceback (most recent call last):
  File "E:/python_project/CMB-Py/dataManage/serverHandler/InsertGDB_update_multi.py", line 91, in ConvertGDB
    shutil.copytree(gdbServerPath, gdbPath)
  File "C:\Python27\ArcGIS10.2\lib\shutil.py", line 206, in copytree
    raise Error, errors
Error: [('D:\\dataHandle\\GISData\\arcgisserver\\gdb\\crm\\clientdata\\clientdata.gdb\\_gdb.T450.3236.8460.sr.lock', 'D:\\dataHandle\\GISData\\gdb\\crm\\clientdata\\clientdata.gdb\\_gdb.T450.3236.8460.sr.lock', "[Errno 13] Permission denied: 'D:\\\\dataHandle\\\\GISData\\\\arcgisserver\\\\gdb\\\\crm\\\\clientdata\\\\clientdata.gdb\\\\_gdb.T450.3236.8460.sr.lock'")]

2017-09-14 21:56:54,486 - INFO - insertUpdate ** convert error!
2017-09-14 21:57:15,290 - INFO - start convert GDB...
                       source File Path:C:\Users\esri\Desktop\customerupdate
                       output Path:D:\dataHandle\GISData\gdb\crm\clientdata
                       log Path:E:\python_project\CMB-Py\dataManage\workspace\logs
2017-09-14 21:57:15,290 - INFO - insertUpdate ** update GDB soucefile:C:\Users\esri\Desktop\customerupdate
2017-09-14 21:57:15,400 - INFO - build tempGDB...
2017-09-14 21:57:31,884 - INFO - update layer...
2017-09-14 21:57:32,197 - INFO - update layer include : clientdata116|clientdata110|clientdata102|clientdata134|clientdata100|clientdata130
2017-09-14 21:57:32,479 - WARNING - Failed to execute. Parameters are not valid.
ERROR 000840: The value is not a Feature Layer.
Failed to execute (DeleteFeatures).

2017-09-14 21:57:32,479 - WARNING - Traceback (most recent call last):
  File "E:/python_project/CMB-Py/dataManage/serverHandler/InsertGDB_update_multi.py", line 127, in ConvertGDB
    deleteFeaturesBySelected(gdbPath, key, rowGroup[key])
  File "E:/python_project/CMB-Py/dataManage/serverHandler/InsertGDB_update_multi.py", line 70, in deleteFeaturesBySelected
    ac.deleteFeatures(tmpName)
  File "E:\python_project\CMB-Py\dataManage\serverHandler\arcpyControl\arcpyOp.py", line 244, in deleteFeatures
    arcpy.DeleteFeatures_management(layerPath)
  File "C:\Program Files (x86)\ArcGIS\Desktop10.2\arcpy\arcpy\management.py", line 2301, in DeleteFeatures
    raise e
ExecuteError: Failed to execute. Parameters are not valid.
ERROR 000840: The value is not a Feature Layer.
Failed to execute (DeleteFeatures).


2017-09-14 21:57:32,479 - INFO - insertUpdate ** convert error!
2017-09-14 22:00:13,809 - INFO - start convert GDB...
                       source File Path:C:\Users\esri\Desktop\customerupdate
                       output Path:D:\dataHandle\GISData\gdb\crm\clientdata
                       log Path:E:\python_project\CMB-Py\dataManage\workspace\logs
2017-09-14 22:00:13,809 - INFO - insertUpdate ** update GDB soucefile:C:\Users\esri\Desktop\customerupdate
2017-09-14 22:00:13,982 - INFO - build tempGDB...
2017-09-14 22:00:30,956 - INFO - update layer...
2017-09-14 22:00:31,267 - INFO - update layer include : clientdata116|clientdata110|clientdata102|clientdata134|clientdata100|clientdata130
2017-09-14 22:00:31,549 - WARNING - Failed to execute. Parameters are not valid.
ERROR 000840: The value is not a Feature Layer.
Failed to execute (DeleteFeatures).

2017-09-14 22:00:31,549 - WARNING - Traceback (most recent call last):
  File "E:/python_project/CMB-Py/dataManage/serverHandler/InsertGDB_update_multi.py", line 127, in ConvertGDB
    deleteFeaturesBySelected(gdbPath, key, rowGroup[key])
  File "E:/python_project/CMB-Py/dataManage/serverHandler/InsertGDB_update_multi.py", line 70, in deleteFeaturesBySelected
    ac.deleteFeatures(tmpName)
  File "E:\python_project\CMB-Py\dataManage\serverHandler\arcpyControl\arcpyOp.py", line 245, in deleteFeatures
    arcpy.DeleteFeatures_management(layerPath)
  File "C:\Program Files (x86)\ArcGIS\Desktop10.2\arcpy\arcpy\management.py", line 2301, in DeleteFeatures
    raise e
ExecuteError: Failed to execute. Parameters are not valid.
ERROR 000840: The value is not a Feature Layer.
Failed to execute (DeleteFeatures).


2017-09-14 22:00:31,549 - INFO - insertUpdate ** convert error!
2017-09-14 22:01:19,401 - INFO - start convert GDB...
                       source File Path:C:\Users\esri\Desktop\customerupdate
                       output Path:D:\dataHandle\GISData\gdb\crm\clientdata
                       log Path:E:\python_project\CMB-Py\dataManage\workspace\logs
2017-09-14 22:01:19,401 - INFO - insertUpdate ** update GDB soucefile:C:\Users\esri\Desktop\customerupdate
2017-09-14 22:01:19,573 - INFO - build tempGDB...
2017-09-14 22:01:39,066 - INFO - update layer...
2017-09-14 22:01:39,411 - INFO - update layer include : clientdata116|clientdata110|clientdata102|clientdata134|clientdata100|clientdata130
2017-09-14 22:01:42,755 - INFO - insert tempGDB to gdb...
2017-09-14 22:01:47,989 - INFO - insertUpdate ** update GDB soucefile:C:\Users\esri\Desktop\customerupdate  complate！
2017-09-14 22:01:47,989 - INFO - insertUpdate ** convert success!
2017-09-14 22:06:22,230 - INFO - start convert GDB...
                       source File Path:C:\Users\esri\Desktop\customerupdate
                       output Path:D:\dataHandle\GISData\gdb\crm\clientdata
                       log Path:E:\python_project\CMB-Py\dataManage\workspace\logs
2017-09-14 22:06:22,230 - INFO - insertUpdate ** update GDB soucefile:C:\Users\esri\Desktop\customerupdate
2017-09-14 22:06:22,369 - INFO - build tempGDB...
2017-09-14 22:06:39,260 - INFO - update layer...
2017-09-14 22:06:39,635 - INFO - update layer include : clientdata116|clientdata110|clientdata102|clientdata134|clientdata100|clientdata130
2017-09-14 22:06:42,901 - INFO - insert tempGDB to gdb...
2017-09-14 22:06:48,198 - INFO - insertUpdate ** update GDB soucefile:C:\Users\esri\Desktop\customerupdate  complate！
2017-09-14 22:06:48,198 - INFO - insertUpdate ** convert success!
2017-09-14 22:23:44,242 - INFO - start convert GDB...
                       source File Path:C:\Users\esri\Desktop\customerupdate
                       output Path:D:\dataHandle\GISData\gdb\crm\clientdata
                       log Path:E:\python_project\CMB-Py\dataManage\workspace\logs
2017-09-14 22:23:44,242 - INFO - insertUpdate ** update GDB soucefile:C:\Users\esri\Desktop\customerupdate
2017-09-14 22:23:44,382 - INFO - build tempGDB...
2017-09-14 22:24:01,441 - INFO - update layer...
2017-09-14 22:24:01,816 - INFO - update layer include : clientdata116|clientdata110|clientdata102|clientdata134|clientdata100|clientdata130
2017-09-14 22:24:05,380 - INFO - insert tempGDB to gdb...
2017-09-14 22:24:10,614 - INFO - insertUpdate ** update GDB soucefile:C:\Users\esri\Desktop\customerupdate  complate！
2017-09-14 22:24:10,614 - INFO - insertUpdate ** convert success!
