2017-07-19 14:05:36,390 - INFO - start convert GDB...
                   source File Path:C:\Users\LocalUser\Desktop\customer50000000111
                   output GDBPath:d:\5000W
                   log Path:D:/python_project/CMB-Py/dataManage\workspace\logs
2017-07-19 14:05:36,492 - INFO - d:\
2017-07-19 14:05:36,492 - INFO - 5000W
2017-07-19 14:05:42,638 - WARNING - 
2017-07-19 14:05:42,640 - WARNING - Traceback (most recent call last):
  File "D:/python_project/CMB-Py/dataManage/serverHandler/InsertGDB_large.py", line 55, in buildGDB
    for f in os.listdir(sourceFilePath):
WindowsError: [Error 267] : 'C:\\Users\\LocalUser\\Desktop\\customer50000000111/*.*'

2017-07-19 14:05:42,640 - INFO - inserGDB_large pid(werw) error!
2017-07-19 14:06:05,482 - INFO - start convert GDB...
                   source File Path:C:\Users\LocalUser\Desktop\customer50000000111
                   output GDBPath:d:\5000W
                   log Path:D:/python_project/CMB-Py/dataManage\workspace\logs
2017-07-19 14:06:05,483 - INFO - d:\
2017-07-19 14:06:05,483 - INFO - 5000W
2017-07-19 14:06:08,595 - WARNING - ERROR 000258: 输出 d:\5000W.gdb 已存在
执行(CreateFileGDB)失败。

2017-07-19 14:06:08,598 - WARNING - Traceback (most recent call last):
  File "D:/python_project/CMB-Py/dataManage/serverHandler/InsertGDB_large.py", line 52, in buildGDB
    ac.createFileGDB(p1, p2)
  File "D:/python_project/CMB-Py/dataManage/serverHandler\arcpyOp.py", line 22, in createFileGDB
    arcpy.CreateFileGDB_management(localWorkspace, name)
  File "C:\Program Files (x86)\ArcGIS\Desktop10.4\ArcPy\arcpy\management.py", line 17017, in CreateFileGDB
    raise e
ExecuteError: ERROR 000258: 输出 d:\5000W.gdb 已存在
执行(CreateFileGDB)失败。


2017-07-19 14:06:08,598 - INFO - inserGDB_large pid(werw) error!
2017-07-19 14:06:24,848 - INFO - start convert GDB...
                   source File Path:C:\Users\LocalUser\Desktop\customer50000000111
                   output GDBPath:d:\5000W
                   log Path:D:/python_project/CMB-Py/dataManage\workspace\logs
2017-07-19 14:06:28,778 - INFO - d:\
2017-07-19 14:06:29,020 - INFO - 5000W
2017-07-19 14:06:38,059 - WARNING - ERROR 000258: 输出 d:\5000W.gdb 已存在
执行(CreateFileGDB)失败。

2017-07-19 14:06:39,940 - WARNING - Traceback (most recent call last):
  File "D:/python_project/CMB-Py/dataManage/serverHandler/InsertGDB_large.py", line 52, in buildGDB
    ac.createFileGDB(p1, p2)
  File "D:/python_project/CMB-Py/dataManage/serverHandler\arcpyOp.py", line 22, in createFileGDB
    arcpy.CreateFileGDB_management(localWorkspace, name)
  File "C:\Program Files (x86)\ArcGIS\Desktop10.4\ArcPy\arcpy\management.py", line 17017, in CreateFileGDB
    raise e
ExecuteError: ERROR 000258: 输出 d:\5000W.gdb 已存在
执行(CreateFileGDB)失败。


2017-07-19 14:06:39,957 - INFO - inserGDB_large pid(werw) error!
2017-07-19 14:07:51,601 - INFO - start convert GDB...
                   source File Path:C:\Users\LocalUser\Desktop\customer50000000111
                   output GDBPath:d:\5000W
                   log Path:D:/python_project/CMB-Py/dataManage\workspace\logs
2017-07-19 14:07:51,604 - INFO - d:\
2017-07-19 14:07:51,605 - INFO - 5000W
2017-07-19 14:07:54,563 - WARNING - 
2017-07-19 14:07:54,563 - WARNING - Traceback (most recent call last):
  File "D:/python_project/CMB-Py/dataManage/serverHandler/InsertGDB_large.py", line 55, in buildGDB
    for f in os.listdir(sourceFilePath):
WindowsError: [Error 267] : 'C:\\Users\\LocalUser\\Desktop\\customer50000000111/*.*'

2017-07-19 14:07:54,569 - INFO - inserGDB_large pid(werw) error!
2017-07-19 14:08:25,674 - INFO - start convert GDB...
                   source File Path:C:\Users\LocalUser\Desktop\customer50000000111
                   output GDBPath:d:\5000W
                   log Path:D:/python_project/CMB-Py/dataManage\workspace\logs
2017-07-19 14:09:01,329 - INFO - start convert GDB...
                   source File Path:C:\Users\LocalUser\Desktop\customer50000000111
                   output GDBPath:d:\5000W\customer.gdb
                   log Path:D:/python_project/CMB-Py/dataManage\workspace\logs
2017-07-19 14:09:19,641 - INFO - d:\5000W
2017-07-19 14:09:19,980 - INFO - customer.gdb
2017-07-19 14:10:28,072 - INFO - start convert GDB...
                   source File Path:C:\Users\LocalUser\Desktop\testfile
                   output GDBPath:d:\5000W\customer.gdb
                   log Path:D:/python_project/CMB-Py/dataManage\workspace\logs
2017-07-19 14:10:34,595 - INFO - d:\5000W
2017-07-19 14:10:34,596 - INFO - customer.gdb
2017-07-19 14:10:39,036 - INFO - convert file:customer50000000111
2017-07-19 14:13:07,009 - INFO - start convert GDB...
                   source File Path:C:\Users\LocalUser\Desktop\testfile
                   output GDBPath:d:\5000W\customer.gdb
                   log Path:D:\python_project\CMB-Py\dataManage\workspace\logs
2017-07-19 14:13:07,015 - INFO - d:\5000W
2017-07-19 14:13:07,016 - INFO - customer.gdb
2017-07-19 14:13:12,936 - INFO - convert file:customer50000000111
2017-07-19 14:13:15,384 - INFO - convert file:customer50000000112
2017-07-19 14:13:20,101 - INFO - inserGDB_large pid(werw) success!
2017-07-19 15:15:16,247 - INFO - start convert GDB...
                   source File Path:C:\Users\LocalUser\Desktop\testfile
                   output GDBPath:d:\5000W\customer.gdb
                   log Path:D:\python_project\CMB-Py\dataManage\workspace\logs
2017-07-19 15:15:16,255 - INFO - d:\5000W
2017-07-19 15:15:16,255 - INFO - customer.gdb
2017-07-19 15:15:21,838 - INFO - convert file:client
2017-07-19 15:15:23,125 - WARNING - insertRow_Point:analysis file failed-C:\Users\LocalUser\Desktop\testfile\client ！
2017-07-19 15:15:23,144 - WARNING - Traceback (most recent call last):
  File "D:\python_project\CMB-Py\dataManage\serverHandler\arcpyOp.py", line 102, in insertRow_Point
    if str(values[x]) != '' and str(values[y]) != "" and str(values[x]) != "0" and str(
IndexError: list index out of range

2017-07-19 15:15:23,144 - WARNING - list index out of range
2017-07-19 15:15:23,144 - WARNING - Traceback (most recent call last):
  File "D:\python_project\CMB-Py\dataManage\serverHandler\arcpyOp.py", line 102, in insertRow_Point
    if str(values[x]) != '' and str(values[y]) != "" and str(values[x]) != "0" and str(
IndexError: list index out of range

2017-07-19 15:15:23,144 - WARNING - Traceback (most recent call last):
  File "D:/python_project/CMB-Py/dataManage/serverHandler/InsertGDB_large.py", line 35, in mapProcess
    return [fileName, os.path.split(outputGDBPath)[1] + os.path.sep + fileName, extent, fileName.split('_')[1]]
IndexError: list index out of range

2017-07-19 15:15:23,144 - WARNING - list index out of range
2017-07-19 15:15:23,144 - WARNING - Traceback (most recent call last):
  File "D:/python_project/CMB-Py/dataManage/serverHandler/InsertGDB_large.py", line 58, in buildGDB
    extent = mapProcess(targetFile, x, y, sourceFileFields, gdbPath)
  File "D:/python_project/CMB-Py/dataManage/serverHandler/InsertGDB_large.py", line 35, in mapProcess
    return [fileName, os.path.split(outputGDBPath)[1] + os.path.sep + fileName, extent, fileName.split('_')[1]]
IndexError: list index out of range

2017-07-19 15:15:23,144 - INFO - inserGDB_large pid(werw) error!
2017-07-19 15:15:55,515 - INFO - start convert GDB...
                   source File Path:C:\Users\LocalUser\Desktop\testfile
                   output GDBPath:d:\5000W\customer.gdb
                   log Path:D:\python_project\CMB-Py\dataManage\workspace\logs
2017-07-19 15:15:55,520 - INFO - d:\5000W
2017-07-19 15:15:55,520 - INFO - customer.gdb
2017-07-19 15:16:01,806 - INFO - convert file:client
2017-07-19 15:16:03,223 - WARNING - insertRow_Point:analysis file failed-C:\Users\LocalUser\Desktop\testfile\client ！
2017-07-19 15:16:03,223 - WARNING - Traceback (most recent call last):
  File "D:\python_project\CMB-Py\dataManage\serverHandler\arcpyOp.py", line 102, in insertRow_Point
    if str(values[x]) != '' and str(values[y]) != "" and str(values[x]) != "0" and str(
IndexError: list index out of range

2017-07-19 15:16:03,223 - WARNING - list index out of range
2017-07-19 15:16:03,223 - WARNING - Traceback (most recent call last):
  File "D:\python_project\CMB-Py\dataManage\serverHandler\arcpyOp.py", line 102, in insertRow_Point
    if str(values[x]) != '' and str(values[y]) != "" and str(values[x]) != "0" and str(
IndexError: list index out of range

2017-07-19 15:16:03,223 - WARNING - Traceback (most recent call last):
  File "D:/python_project/CMB-Py/dataManage/serverHandler/InsertGDB_large.py", line 35, in mapProcess
    return [fileName, os.path.split(outputGDBPath)[1] + os.path.sep + fileName, extent, fileName.split('_')[1]]
IndexError: list index out of range

2017-07-19 15:16:03,223 - WARNING - list index out of range
2017-07-19 15:16:03,223 - WARNING - Traceback (most recent call last):
  File "D:/python_project/CMB-Py/dataManage/serverHandler/InsertGDB_large.py", line 58, in buildGDB
    extent = mapProcess(targetFile, x, y, sourceFileFields, gdbPath)
  File "D:/python_project/CMB-Py/dataManage/serverHandler/InsertGDB_large.py", line 35, in mapProcess
    return [fileName, os.path.split(outputGDBPath)[1] + os.path.sep + fileName, extent, fileName.split('_')[1]]
IndexError: list index out of range

2017-07-19 15:16:03,223 - INFO - inserGDB_large pid(werw) error!
2017-07-19 15:16:13,651 - INFO - start convert GDB...
                   source File Path:C:\Users\LocalUser\Desktop\testfile
                   output GDBPath:d:\5000W\customer.gdb
                   log Path:D:/python_project/CMB-Py/dataManage\workspace\logs
2017-07-19 15:16:20,838 - INFO - d:\5000W
2017-07-19 15:16:21,237 - INFO - customer.gdb
2017-07-19 15:16:37,798 - INFO - convert file:client
2017-07-19 15:18:40,487 - INFO - start convert GDB...
                   source File Path:C:\Users\LocalUser\Desktop\testfile
                   output GDBPath:d:\5000W\customer.gdb
                   log Path:D:\python_project\CMB-Py\dataManage\workspace\logs
2017-07-19 15:18:40,493 - INFO - d:\5000W
2017-07-19 15:18:40,493 - INFO - customer.gdb
2017-07-19 15:18:46,247 - INFO - convert file:customer5000000011_1
2017-07-19 15:18:48,688 - INFO - convert file:customer5000000011_2
2017-07-19 15:18:53,244 - INFO - inserGDB_large pid(werw) success!
